version: '3.8'

services:
  adminer:
    container_name: adminer
    hostname: adminer
    build:
      context: .
      dockerfile: ./services/adminer/Dockerfile
    ports:
      - "8080:8080"
    volumes:
      - ./services/adminer/adminer-data:/var/lib/adminer/adminer-data
    networks:
      - main

  db:
    container_name: db
    hostname: db
    build:
      context: .
      dockerfile: ./services/db/Dockerfile
    ports:
      - "5432:5432"
    healthcheck:
      test: ["CMD-SHELL", "pg_isready -U localhost -d piscineds"]
      interval: 10s
      timeout: 5s
      retries: 3
    volumes:
      - ./services/db/db-data:/var/lib/postgresql/db-data
    networks:
      - main

  python-runner:
    container_name: python-runner
    hostname: python-runner
    build:
      context: .
      dockerfile: ./services/python-runner/Dockerfile
    depends_on:
      db:
        condition: service_healthy
    tty: true
    volumes:
      - ./services/python-runner/python-runner-data:/var/lib/python-runner/python-runner-data
    networks:
      - main

networks:
  main:
    name: main
    driver: bridge

volumes:
  adminer-data:
    name: adminer-data
    driver: bridge
  db-data:
    name: db-data
    driver: bridge
  python-runner-data:
    name: python-runner-data
    driver: bridge